Workbook

Sheet Read me
A1: Revocup Coffee Roasters · New customer acquisition model
A2: Prepared by EmberTribe, updated October 15, 2026. Internal working model for the 90-day paid social test.
A4: How to use it
A5: 1. Change the yellow cells on the Inputs tab (ad spend, cost per click, conversion rate, margin, fees, customer value case).
A6: 2. CAC grid shows what a new customer costs at each cost per click and conversion rate, colored against break-even.
A7: 3. 90-day model shows customers acquired, payback timing, and year-one profit at three customer costs, plus the one implied by your Inputs.
A8: 4. Shopify data holds the numbers behind the customer value curve. Edit only if you re-pull the export.
A10: Color legend
A11: Blue text = typed-in inputs or data. Black text = formulas. Green text = pulled from another tab. Yellow fill = the levers to change.
A13: Sources and caveats
A14: Shopify order and customer exports pulled October 13, 2026 (orders Oct 24, 2024 to Oct 13, 2026). Two of Habte's own test accounts excluded.
A15: Customer value uses product revenue (order subtotal), not shipping or tax. Shipping is charged to customers (about $8.76 an order) and assumed to cover shipping cost.
... A19: Sample is small (134 customers; 61 with a full year of history). Paid-social buyers may reorder less than today's mostly word-of-mouth buyers, so the Base case uses out-of-state customers and Conservative cuts that by 30%.

Sheet Inputs
A1: Inputs · change the yellow cells
A3: Lever | B3: Value | C3: Where it comes from
A4: Monthly ad spend | B4: 5000 | C4: Habte, Oct 12 call; Oct 15: flexible, from $3,000
A5: Test length (months) | B5: 3 | C5: 90-day sprint
A6: Gross margin on product | B6: 0.6 | C6: Habte, Oct 15 call: about 60% on roasted beans, possibly lower
A7: Cost per click (Meta) | B7: 1 | C7: Illustrative. Read the real number after week 2
A8: Site conversion rate, first-time paid visitors | B8: 0.01 | C8: Target after store fixes. Today about 0.3% of visits bring in a new customer (0.82% counting repeat orders)
A9: EmberTribe monthly fees | B9: 1750 | C9: Meta + Google management, discounted Oct 15 (standard $2,500 one channel). Add $2,000 for email/SMS campaigns
A10: One-time site redesign | B10: 5000 | C10: Elite Launch at $5,000 with a 90-day paid media commitment signed by Oct 31, 2026 ($9,999 alone)
A11: Customer value case (1, 2 or 3) | B11: 2 | C11: 1 = Conservative, 2 = Base, 3 = Strong (see below)
A13: Customer value cases · product $ per new customer
A14: Case | B14: Year one | C14: Basis
A15: 1 · Conservative | B15: =ROUND('Shopify data'!D32*0.7,2) | C15: Out-of-state customers cut by 30%, for paid buyers who reorder less
A16: 2 · Base | B16: ='Shopify data'!D32 | C16: Out-of-state customers today (closest match to buyers found through ads)
A17: 3 · Strong | B17: ='Shopify data'!B32 | C17: All customers today, including local regulars
A19: Derived
A20: Selected year-one product $ per customer | B20: =INDEX(B15:B17,B11)
A21: Year-one gross profit per customer (= break-even cost per customer) | B21: =B20*B6
A22: First-order product $ per customer | B22: ='Shopify data'!D26
A23: First-order gross profit (= first-order break-even) | B23: =B22*B6
A24: Break-even return on ad spend, first order | B24: =IF(B6=0,0,1/B6)
A25: Cost per new customer from your click cost and conversion | B25: =IF(B8=0,0,B7/B8)
A26: Total ad spend over the test | B26: =B4*B5
A27: Total EmberTribe fees over the test | B27: =B9*B5+B10
A28: New customers per month today | B28: ='Shopify data'!B10

Sheet CAC grid
A1: What a new customer costs · cost per click ÷ conversion rate
A2: Green = pays back on the first order. Yellow = pays back within year one (selected case). Red = does not pay back in year one.
A4: Cost per click ↓ / conversion → | B4: 0.003 | C4: 0.005 | D4: 0.01 | E4: 0.015 | F4: 0.02 | G4: 0.025
A5: 0.5 | B5: =IF(B$4=0,0,$A5/B$4) | C5: =IF(C$4=0,0,$A5/C$4) | D5: =IF(D$4=0,0,$A5/D$4) | E5: =IF(E$4=0,0,$A5/E$4) | F5: =IF(F$4=0,0,$A5/F$4) | G5: =IF(G$4=0,0,$A5/G$4)
A6: 0.75 | B6: =IF(B$4=0,0,$A6/B$4) | C6: =IF(C$4=0,0,$A6/C$4) | D6: =IF(D$4=0,0,$A6/D$4) | E6: =IF(E$4=0,0,$A6/E$4) | F6: =IF(F$4=0,0,$A6/F$4) | G6: =IF(G$4=0,0,$A6/G$4)
A7: 1 | B7: =IF(B$4=0,0,$A7/B$4) | C7: =IF(C$4=0,0,$A7/C$4) | D7: =IF(D$4=0,0,$A7/D$4) | E7: =IF(E$4=0,0,$A7/E$4) | F7: =IF(F$4=0,0,$A7/F$4) | G7: =IF(G$4=0,0,$A7/G$4)
A8: 1.25 | B8: =IF(B$4=0,0,$A8/B$4) | C8: =IF(C$4=0,0,$A8/C$4) | D8: =IF(D$4=0,0,$A8/D$4) | E8: =IF(E$4=0,0,$A8/E$4) | F8: =IF(F$4=0,0,$A8/F$4) | G8: =IF(G$4=0,0,$A8/G$4)
A9: 1.5 | B9: =IF(B$4=0,0,$A9/B$4) | C9: =IF(C$4=0,0,$A9/C$4) | D9: =IF(D$4=0,0,$A9/D$4) | E9: =IF(E$4=0,0,$A9/E$4) | F9: =IF(F$4=0,0,$A9/F$4) | G9: =IF(G$4=0,0,$A9/G$4)
A10: 2 | B10: =IF(B$4=0,0,$A10/B$4) | C10: =IF(C$4=0,0,$A10/C$4) | D10: =IF(D$4=0,0,$A10/D$4) | E10: =IF(E$4=0,0,$A10/E$4) | F10: =IF(F$4=0,0,$A10/F$4) | G10: =IF(G$4=0,0,$A10/G$4)
A12: First-order break-even | B12: =Inputs!B23
A13: Year-one break-even | B13: =Inputs!B21
A15: 0.3% is the rate at which a visit brings in a NEW customer today (73 new customers over 25,519 human sessions, last 12 months). All orders over sessions is 0.82%, but about two-thirds of orders are repeat buyers, and ad visitors are all first-time.

Sheet 90-day model
A1: 90-day test · what the ad spend buys
A2: Uses the selected customer value case on Inputs. Customer value is product revenue only. Year-one profit counts each customer for a full year from their first order.
B4: Strong | C4: Middle | D4: Weak | E4: From your Inputs | F4: Days | G4: Cum. gross profit
A5: Cost per new customer | B5: 50 | C5: 75 | D5: 100 | E5: =Inputs!B25
A6: New customers over the test | B6: =IF(B5=0,0,Inputs!$B$26/B5) | C6: =IF(C5=0,0,Inputs!$B$26/C5) | D6: =IF(D5=0,0,Inputs!$B$26/D5) | E6: =IF(E5=0,0,Inputs!$B$26/E5) | F6: ='Shopify data'!A26 | G6: ='Shopify data'!D26/'Shopify data'!$D$32*Inputs!$B$20*Inputs!$B$6
A7: vs. new customers at today's pace | B7: =Inputs!$B$28*Inputs!$B$5 | C7: =Inputs!$B$28*Inputs!$B$5 | D7: =Inputs!$B$28*Inputs!$B$5 | E7: =Inputs!$B$28*Inputs!$B$5 | F7: ='Shopify data'!A27 | G7: ='Shopify data'!D27/'Shopify data'!$D$32*Inputs!$B$20*Inputs!$B$6
A8: First-order product revenue | B8: =B6*Inputs!$B$22 | C8: =C6*Inputs!$B$22 | D8: =D6*Inputs!$B$22 | E8: =E6*Inputs!$B$22 | F8: ='Shopify data'!A28 | G8: ='Shopify data'!D28/'Shopify data'!$D$32*Inputs!$B$20*Inputs!$B$6
A9: Year-one product revenue | B9: =B6*Inputs!$B$20 | C9: =C6*Inputs!$B$20 | D9: =D6*Inputs!$B$20 | E9: =E6*Inputs!$B$20 | F9: ='Shopify data'!A29 | G9: ='Shopify data'!D29/'Shopify data'!$D$32*Inputs!$B$20*Inputs!$B$6
A10: Year-one gross profit | B10: =B9*Inputs!$B$6 | C10: =C9*Inputs!$B$6 | D10: =D9*Inputs!$B$6 | E10: =E9*Inputs!$B$6 | F10: ='Shopify data'!A30 | G10: ='Shopify data'!D30/'Shopify data'!$D$32*Inputs!$B$20*Inputs!$B$6
A11: Minus ad spend | B11: =-Inputs!$B$26 | C11: =-Inputs!$B$26 | D11: =-Inputs!$B$26 | E11: =-Inputs!$B$26 | F11: ='Shopify data'!A31 | G11: ='Shopify data'!D31/'Shopify data'!$D$32*Inputs!$B$20*Inputs!$B$6
A12: Year one after ad spend | B12: =B10+B11 | C12: =C10+C11 | D12: =D10+D11 | E12: =E10+E11 | F12: ='Shopify data'!A32 | G12: ='Shopify data'!D32/'Shopify data'!$D$32*Inputs!$B$20*Inputs!$B$6
A13: Minus EmberTribe fees | B13: =-Inputs!$B$27 | C13: =-Inputs!$B$27 | D13: =-Inputs!$B$27 | E13: =-Inputs!$B$27
A14: Year one after ad spend and fees | B14: =B12+B13 | C14: =C12+C13 | D14: =D12+D13 | E14: =E12+E13 | F14: Helper: out-of-state value curve, scaled to the selected case.
A15: First-order return on ad spend | B15: =IF(Inputs!$B$26=0,0,B8/Inputs!$B$26) | C15: =IF(Inputs!$B$26=0,0,C8/Inputs!$B$26) | D15: =IF(Inputs!$B$26=0,0,D8/Inputs!$B$26) | E15: =IF(Inputs!$B$26=0,0,E8/Inputs!$B$26)
A16: Days until a customer pays back their cost | B16: =IF(COUNTIF($G$6:$G$12,"<"&B5)>=7,"Over 365",INDEX($F$6:$F$12,COUNTIF($G$6:$G$12,"<"&B5)+1)) | C16: =IF(COUNTIF($G$6:$G$12,"<"&C5)>=7,"Over 365",INDEX($F$6:$F$12,COUNTIF($G$6:$G$12,"<"&C5)+1)) | D16: =IF(COUNTIF($G$6:$G$12,"<"&D5)>=7,"Over 365",INDEX($F$6:$F$12,COUNTIF($G$6:$G$12,"<"&D5)+1)) | E16: =IF(COUNTIF($G$6:$G$12,"<"&E5)>=7,"Over 365",INDEX($F$6:$F$12,COUNTIF($G$6:$G$12,"<"&E5)+1))
A18: Reading it: payback is when a customer's cumulative gross profit covers what they cost to win. Repeat orders arrive slowly (median 54 days to a second order), so a 90-day test shows only part of the payoff.

Sheet Shopify data
A1: Shopify data · aggregated from the Oct 13, 2026 exports
A3: Store summary | B3: Value
A4: Date range | B4: Oct 24, 2024 – Oct 13, 2026
A5: Customers (excl. 2 test accounts) | B5: 134
A6: Orders | B6: 383
A7: Revenue, all orders incl. shipping | B7: 24453
A8: Revenue, last 12 months | B8: 15786
A9: Orders per month, last 12 months | B9: 20.5
A10: New customers per month, last 12 months | B10: 6.1
A11: Most orders in any month | B11: 31
A12: Average first order, product only | B12: 56.14
A13: Average first order incl. shipping | B13: 64.73
A14: Average shipping charged per order | B14: 8.76
A15: Customers who ordered 2+ times | B15: 0.338
A16: Revenue from repeat customers | B16: 0.768
... A22: Customers opted in to email | B22: 55
A24: Customer value curve · same customers followed over time (61 with a full year; 28 of them outside KS/MO)
A25: Days since first order | B25: All: product $ per customer | C25: All: % reordered | D25: Out-of-state: product $ | E25: Out-of-state: % reordered
A26: 0 | B26: 56.77 | C26: 0 | D26: 58.3 | E26: 0
A27: 30 | B27: 60.33 | C27: 0.082 | D27: 62.2 | E27: 0.107
A28: 60 | B28: 74.61 | C28: 0.262 | D28: 70.31 | E28: 0.25
A29: 90 | B29: 87 | C29: 0.344 | D29: 79.6 | E29: 0.321
A30: 180 | B30: 129.35 | C30: 0.459 | D30: 118.92 | E30: 0.464
A31: 270 | B31: 161.69 | C31: 0.475 | D31: 139.03 | E31: 0.464
A32: 365 | B32: 192.79 | C32: 0.492 | D32: 158.31 | E32: 0.464
A34: Monthly orders · new vs returning customers
A35: Month | B35: New customers | C35: Returning orders | D35: Returning share
A36: 2025-02 | B36: 11 | C36: 3 | D36: =IF(B36+C36=0,0,C36/(B36+C36))
A37: 2025-03 | B37: 8 | C37: 4 | D37: =IF(B37+C37=0,0,C37/(B37+C37))
A38: 2025-04 | B38: 10 | C38: 6 | D38: =IF(B38+C38=0,0,C38/(B38+C38))
A39: 2025-05 | B39: 5 | C39: 11 | D39: =IF(B39+C39=0,0,C39/(B39+C39))
A40: 2025-06 | B40: 7 | C40: 10 | D40: =IF(B40+C40=0,0,C40/(B40+C40))
A41: 2025-07 | B41: 5 | C41: 14 | D41: =IF(B41+C41=0,0,C41/(B41+C41))
A42: 2025-08 | B42: 6 | C42: 11 | D42: =IF(B42+C42=0,0,C42/(B42+C42))
A43: 2025-09 | B43: 6 | C43: 12 | D43: =IF(B43+C43=0,0,C43/(B43+C43))
A44: 2025-10 | B44: 4 | C44: 11 | D44: =IF(B44+C44=0,0,C44/(B44+C44))
A45: 2025-11 | B45: 7 | C45: 17 | D45: =IF(B45+C45=0,0,C45/(B45+C45))
A46: 2025-12 | B46: 14 | C46: 17 | D46: =IF(B46+C46=0,0,C46/(B46+C46))
A47: 2026-01 | B47: 5 | C47: 13 | D47: =IF(B47+C47=0,0,C47/(B47+C47))
... A55: 2026-09 | B55: 4 | C55: 12 | D55: =IF(B55+C55=0,0,C55/(B55+C55))
...
